    distrib_run.run(args)
  File "/root/.cache/pypoetry/virtualenvs/mini-r1-dvGMjUhU-py3.12/lib/python3.12/site-packages/torch/distributed/run.py", line 910, in run
    elastic_launch(
  File "/root/.cache/pypoetry/virtualenvs/mini-r1-dvGMjUhU-py3.12/lib/python3.12/site-packages/torch/distributed/launcher/api.py", line 138, in __call__
    return launch_agent(self._config, self._entrypoint, list(args))
           ^^^^^^^^^^^^^^^^^^^^^^^^^^^^^^^^^^^^^^^^^^^^^^^^^^^^^^^^
  File "/root/.cache/pypoetry/virtualenvs/mini-r1-dvGMjUhU-py3.12/lib/python3.12/site-packages/torch/distributed/launcher/api.py", line 269, in launch_agent
    raise ChildFailedError(
torch.distributed.elastic.multiprocessing.errors.ChildFailedError: 
============================================================
main.py FAILED
------------------------------------------------------------
Failures:
  <NO_OTHER_FAILURES>
------------------------------------------------------------
Root Cause (first observed failure):
[0]:
  time      : 2025-02-15_01:47:53
  host      : autodl-container-11494a9380-19d0eafd
  rank      : 0 (local_rank: 0)
  exitcode  : 1 (pid: 3634)
  error_file: <N/A>
  traceback : To enable traceback see: https://pytorch.org/docs/stable/elastic/errors.html
============================================================
root@autodl-container-11494a9380-19d0eafd:~/Mini-R1# 